Workbook

Sheet KA
A1: Mandya | B1: Debit | G1: ASM | H1: Mandya | I1: Pending Bills | J1: (< 15 days ) | K1: 15 to 30 days | L1: 30 to 45 days | M1: 45 to 60 days | N1: 60 to 90 days | O1: 90 to 180 days | P1: 180 to 365 days | Q1: 365 to 730 days | R1: (> 730 days )
A2: Abhishek Poultry Farm K Shetthali | B2: 30300 | D2: =VLOOKUP(A2,$H$2:$I$105,2,0) -> 30300 | E2: =+B2-D2 -> 0 | G2: Direct - Active | H2: Chowdayya Poultry Farms Malavalli | I2: =SUM(J2:R2) -> 13625 | N2: 13625
A3: Akash Pig Farm | B3: 6570 | D3: =VLOOKUP(A3,$H$2:$I$105,2,0) -> 6570 | E3: =+B3-D3 -> 0 | G3: Direct - Active | H3: G.P.P.Poultry Farm | I3: =SUM(J3:R3) -> 4307350 | J3: 912190 | K3: 1141200 | L3: 900410 | M3: 686000 | N3: 667550
A4: Amol Pig Farm | B4: 104690 | D4: =VLOOKUP(A4,$H$2:$I$105,2,0) -> 104690 | E4: =+B4-D4 -> 0 | G4: Direct - Active | H4: Javare Gowda Dairy Farm | I4: =SUM(J4:R4) -> 8815 | N4: 3320 | O4: 5495
A5: Ananya Poultry Farm & Supplies | B5: 54000 | D5: =VLOOKUP(A5,$H$2:$I$105,2,0) -> 54000 | E5: =+B5-D5 -> 0 | G5: Direct - Active | H5: Jogi Gowda Poultry Farm | I5: =SUM(J5:R5) -> 86330 | J5: 27230 | K5: 59100
A6: Ashok Poultry Farm_x000D_ | B6: 599850 | D6: =VLOOKUP(A6,$H$2:$I$105,2,0) -> 599850 | E6: =+B6-D6 -> 0 | G6: Direct - Active | H6: K G Satya Poultry Farm | I6: =SUM(J6:R6) -> 367278 | J6: =375200-192112 -> 183088 | K6: 95800 | M6: 88390
A7: Associate Professor Dept.of ILFC Dairy | B7: 8911 | D7: =VLOOKUP(A7,$H$2:$I$105,2,0) -> 8911 | E7: =+B7-D7 -> 0 | G7: Direct - Active | H7: Krishna Poultry Farm | I7: =SUM(J7:R7) -> 2754944.5 | K7: 225100 | M7: 186650 | N7: 174300 | O7: 1702445 | P7: =680294.52-213845 -> 466449.52
A8: Bandipura Breeders, Mysore | B8: 933158 | D8: =VLOOKUP(A8,$H$2:$I$105,2,0) -> 933158 | E8: =+B8-D8 -> 0 | G8: Direct - Active | H8: Kumar Poultry Farm | I8: =SUM(J8:R8) -> 1025 | O8: 1025
A9: BJS Poultry Farm | B9: 306533 | D9: =VLOOKUP(A9,$H$2:$I$105,2,0) -> 306533 | E9: =+B9-D9 -> 0 | G9: Direct - Active | H9: Muralidhar Poultry Farm | I9: =SUM(J9:R9) -> 55445 | J9: 55445
A10: Chaluvaraya Swamy Poultry Farm,Channapatna | B10: 183720 | D10: =VLOOKUP(A10,$H$2:$I$105,2,0) -> 183720 | E10: =+B10-D10 -> 0 | G10: Direct - Active | H10: Nandish Poultry Farm Mandya | I10: =SUM(J10:R10) -> 3950 | M10: 3950
A11: Chowdayya Poultry Farms Malavalli | B11: 13625 | D11: =VLOOKUP(A11,$H$2:$I$105,2,0) -> 13625 | E11: =+B11-D11 -> 0 | G11: Direct - Active | H11: Poonacha PB | I11: =SUM(J11:R11) -> 31300 | L11: 31300
A12: Deeksha Vet Medicals | B12: 52000 | D12: =VLOOKUP(A12,$H$2:$I$105,2,0) -> 52000 | E12: =+B12-D12 -> 0 | G12: Direct - Active | H12: Prasanan Kumar Poultry Farm | I12: =SUM(J12:R12) -> 1280 | O12: 1280
A13: Devapriya Foods & Feeds,Honnavara | B13: 511820 | D13: =VLOOKUP(A13,$H$2:$I$105,2,0) -> 511820 | E13: =+B13-D13 -> 0 | G13: Direct - Active | H13: Prasanna Pig Farm | I13: =SUM(J13:R13) -> 180 | K13: 180
A14: Devaraja Poultry Farm | B14: 461812 | D14: =VLOOKUP(A14,$H$2:$I$105,2,0) -> 461812 | E14: =+B14-D14 -> 0 | G14: Direct - Active | H14: Prathapa Poultry Farm | I14: =SUM(J14:R14) -> 47355 | O14: 47355
A15: G.P.P.Poultry Farm | B15: 4307350 | D15: =VLOOKUP(A15,$H$2:$I$105,2,0) -> 4307350 | E15: =+B15-D15 -> 0 | G15: Direct - Active | H15: Rajatha Poultry Farm | I15: =SUM(J15:R15) -> 8185 | M15: 8185
A16: Gurunatha Poultry Farm | B16: 900848 | D16: =VLOOKUP(A16,$H$2:$I$105,2,0) -> 900848 | E16: =+B16-D16 -> 0 | G16: Direct - Active | H16: Ramesh Poultry Farms | I16: =SUM(J16:R16) -> 56995 | M16: 4270 | N16: 12315 | O16: 40410
A17: Happy Chicken Centre | B17: 1341583 | D17: =VLOOKUP(A17,$H$2:$I$105,2,0) -> 1341583 | E17: =+B17-D17 -> 0 | G17: Direct - Active | H17: Sanjaya.K Poultry Farm | I17: =SUM(J17:R17) -> 4590 | L17: 4590
A18: Harish Poultry Farm- Mandya | B18: 13280 | D18: =VLOOKUP(A18,$H$2:$I$105,2,0) -> 13280 | E18: =+B18-D18 -> 0 | G18: Direct - Active | H18: Sanjay S, Veterinary College Hebbal | I18: =SUM(J18:R18) -> 62003 | N18: 62003
A19: Hunter Chicken & Eggs India (OPC) Pvt Ltd | B19: 753532 | D19: =VLOOKUP(A19,$H$2:$I$105,2,0) -> 753532 | E19: =+B19-D19 -> 0 | G19: Direct - Active | H19: Sathish Poultry Farm ,Maddur | I19: =SUM(J19:R19) -> 22780 | R19: 22780
A20: Javare Gowda Dairy Farm | B20: 8815 | D20: =VLOOKUP(A20,$H$2:$I$105,2,0) -> 8815 | E20: =+B20-D20 -> 0 | G20: Direct - Active | H20: Sharath Poultry Farm | I20: =SUM(J20:R20) -> 113005 | N20: 112200 | O20: 805
A21: Jayalinga Poultry Farm | B21: 131750 | D21: =VLOOKUP(A21,$H$2:$I$105,2,0) -> 131750 | E21: =+B21-D21 -> 0 | G21: Direct - Active | H21: Siddaramu Dairy Farm Kodyala | I21: =SUM(J21:R21) -> 795 | N21: 795
A22: Jayanthi Associates, Kannur | B22: 3222982 | D22: =VLOOKUP(A22,$H$2:$I$105,2,0) -> 3222982 | E22: =+B22-D22 -> 0 | G22: Direct - Active | H22: Sree Lakshmi Ranganatha Poultry Farm & Services | I22: =SUM(J22:R22) -> 589294 | L22: 415500 | N22: 173794
A23: Jayaraju Poultry Farm_x000D_ | B23: 296940 | D23: =VLOOKUP(A23,$H$2:$I$105,2,0) -> 296940 | E23: =+B23-D23 -> 0 | G23: Direct - Active | H23: Sridhar Poultry Farm - Nagamangala | I23: =SUM(J23:R23) -> 10700 | K23: 10700
A24: J K Pig Farm, Chllakere | B24: 1639250 | D24: =VLOOKUP(A24,$H$2:$I$105,2,0) -> 1639250 | E24: =+B24-D24 -> 0 | G24: Direct - Active | H24: Tilk Poultry Farm | I24: =SUM(J24:R24) -> 2060 | M24: 20 | O24: 2040
A25: Jogi Gowda Poultry Farm | B25: 86330 | D25: =VLOOKUP(A25,$H$2:$I$105,2,0) -> 86330 | E25: =+B25-D25 -> 0 | G25: Direct - Active | H25: Udaya Poultry Farm | I25: =SUM(J25:R25) -> 7705 | L25: 7705
A26: Jyothi Poultry Farm | B26: 53935 | D26: =VLOOKUP(A26,$H$2:$I$105,2,0) -> 53935 | E26: =+B26-D26 -> 0 | G26: Direct - Active | H26: Varadaraj Poultry Farm | I26: =SUM(J26:R26) -> 2025 | L26: 2025
A27: Kannadiga Poultry Farm | B27: 950 | D27: =VLOOKUP(A27,$H$2:$I$105,2,0) -> 950 | E27: =+B27-D27 -> 0 | G27: Direct - Active | H27: Veteran Laboratories | I27: =SUM(J27:R27) -> 13775 | Q27: 2600 | R27: 11175
A28: Kempanna Poultry Farm | B28: 4350 | D28: =VLOOKUP(A28,$H$2:$I$105,2,0) -> 4350 | E28: =+B28-D28 -> 0 | G28: Direct - Active | H28: Veterinary Collage Hebbal | I28: =SUM(J28:R28) -> 5928 | O28: 5928
A29: K G Satya Poultry Farm | B29: 367278 | D29: =VLOOKUP(A29,$H$2:$I$105,2,0) -> 367278 | E29: =+B29-D29 -> 0 | G29: Direct - Active | H29: Vishwanatha Poultry Farm | I29: =SUM(J29:R29) -> 2345 | J29: 2345
A30: KPR Agros Poultries Pvt Ltd | B30: 6650 | D30: =VLOOKUP(A30,$H$2:$I$105,2,0) -> 6650 | E30: =+B30-D30 -> 0 | G30: Direct - Active | H30: V N Poultry Farm | I30: =SUM(J30:R30) -> 605 | N30: 605
A31: Krishna Murthy Labour | B31: 2000 | D31: =VLOOKUP(A31,$H$2:$I$105,2,0) -> 2000 | E31: =+B31-D31 -> 0 | G31: Direct - Inactive | H31: Abhishek Poultry Farm K Shetthali | I31: =SUM(J31:R31) -> 30300 | Q31: 30300
A32: Krishna Poultry Farm | B32: 2754944.5 | D32: =VLOOKUP(A32,$H$2:$I$105,2,0) -> 2754944.5 | E32: =+B32-D32 -> 0 | G32: Direct - Inactive | H32: Akash Pig Farm | I32: =SUM(J32:R32) -> 6570 | Q32: 6570
A33: Krishnappa | B33: 594147.4 | D33: =VLOOKUP(A33,$H$2:$I$105,2,0) -> 594147.4 | E33: =+B33-D33 -> 0 | G33: Direct - Inactive | H33: Amol Pig Farm | I33: =SUM(J33:R33) -> 104690 | Q33: 76240 | R33: 28450
A34: Krushie Kushie C/O Rakshitha | B34: 864426 | D34: =VLOOKUP(A34,$H$2:$I$105,2,0) -> 864426 | E34: =+B34-D34 -> 0 | G34: Direct - Inactive | H34: Ananya Poultry Farm & Supplies | I34: =SUM(J34:R34) -> 54000 | R34: 54000
A35: Kumar Poultry Farm | B35: 1025 | D35: =VLOOKUP(A35,$H$2:$I$105,2,0) -> 1025 | E35: =+B35-D35 -> 0 | G35: Direct - Inactive | H35: Ashok Poultry Farm_x000D_ | I35: =SUM(J35:R35) -> 599850 | R35: 599850
A36: Lalitha Farm, Kadur | B36: 36700 | D36: =VLOOKUP(A36,$H$2:$I$105,2,0) -> 36700 | E36: =+B36-D36 -> 0 | G36: Direct - Inactive | H36: Associate Professor Dept.of ILFC Dairy | I36: =SUM(J36:R36) -> 8911 | R36: 8911
A37: Madduramma Poultry Farm | B37: 76200 | D37: =VLOOKUP(A37,$H$2:$I$105,2,0) -> 76200 | E37: =+B37-D37 -> 0 | G37: Direct - Inactive | H37: Bandipura Breeders, Mysore | I37: =SUM(J37:R37) -> 933158 | R37: 933158
A38: Megha Poultry Farm | B38: 317430 | D38: =VLOOKUP(A38,$H$2:$I$105,2,0) -> 317430 | E38: =+B38-D38 -> 0 | G38: Direct - Inactive | H38: BJS Poultry Farm | I38: =SUM(J38:R38) -> 306533 | R38: 306533
A39: M.Nataraja S/O M.R.Muniswamy | B39: 101265 | D39: =VLOOKUP(A39,$H$2:$I$105,2,0) -> 101265 | E39: =+B39-D39 -> 0 | G39: Direct - Inactive | H39: Chaluvaraya Swamy Poultry Farm,Channapatna | I39: =SUM(J39:R39) -> 183720 | R39: 183720
A40: Muralidhar Poultry Farm | B40: 55445 | D40: =VLOOKUP(A40,$H$2:$I$105,2,0) -> 55445 | E40: =+B40-D40 -> 0 | G40: Direct - Inactive | H40: Deeksha Vet Medicals | I40: =SUM(J40:R40) -> 52000 | P40: 52000
...

Sheet TN
A1: Hosur | B1: Debit | G1: ASM | H1: Hosur | I1: Pending Bills | J1: (< 15 days ) | K1: 15 to 30 days | L1: 30 to 45 days | M1: 45 to 60 days | N1: 60 to 90 days | O1: 90 to 180 days | P1: 180 to 365 days | Q1: 365 to 730 days | R1: (> 730 days )
A2: Buruju Gangamma Poultry Farm | B2: 503397 | D2: =VLOOKUP(A2,$H$2:$I$3,2,0) -> 503397 | E2: =+B2-D2 -> 0 | G2: Lavanya | H2: Buruju Gangamma Poultry Farm | I2: =SUM(J2:R2) -> 503397 | J2: 503397
A3: Jaya Kumar Poultry Farm | B3: 1086175 | D3: =VLOOKUP(A3,$H$2:$I$3,2,0) -> 1086175 | E3: =+B3-D3 -> 0 | G3: Ranjith | H3: Jaya Kumar Poultry Farm | I3: =SUM(J3:R3) -> 1086175 | J3: 1086175
A4: Grand Total | B4: =SUM(B2:B3) -> 1589572 | D4: =SUM(D2:D3) -> 1589572 | E4: =SUM(E2:E3) -> 0 | I4: =SUM(I2:I3) -> 1589572 | J4: =SUM(J2:J3) -> 1589572 | K4: =SUM(K2:K3) -> 0 | L4: =SUM(L2:L3) -> 0 | M4: =SUM(M2:M3) -> 0 | N4: =SUM(N2:N3) -> 0 | O4: =SUM(O2:O3) -> 0 | P4: =SUM(P2:P3) -> 0 | ... R4: =SUM(R2:R3) -> 0
A7: Polachi | B7: Debit | G7: ASM | H7: Polachi | I7: Pending Bills | J7: (< 15 days ) | K7: 15 to 30 days | L7: 30 to 45 days | M7: 45 to 60 days | N7: 60 to 90 days | O7: 90 to 180 days | P7: 180 to 365 days | Q7: 365 to 730 days | R7: (> 730 days )
A8: Bismillah Feeds | B8: 2893087.4 | D8: =VLOOKUP(A8,$H$8:$I$17,2,0) -> 2893087.4 | E8: =+B8-D8 -> 0 | G8: Adarsh | H8: Haritha Agencies | I8: =SUM(J8:R8) -> 430700 | J8: 430700
A9: Haritha Agencies | B9: 430700 | D9: =VLOOKUP(A9,$H$8:$I$17,2,0) -> 430700 | E9: =+B9-D9 -> 0 | G9: Adarsh | H9: Royal Traders | I9: =SUM(J9:R9) -> 475 | M9: 475
A10: J K Agencies | B10: 9289726 | D10: =VLOOKUP(A10,$H$8:$I$17,2,0) -> 9289726 | E10: =+B10-D10 -> 0 | G10: Nebu John | H10: Bismillah Feeds | I10: =SUM(J10:R10) -> 2893087.4 | K10: 2893087.4
A11: Matha Agencies | B11: 5070634 | D11: =VLOOKUP(A11,$H$8:$I$17,2,0) -> 5070634 | E11: =+B11-D11 -> 0 | G11: Nebu John | H11: J K Agencies | I11: =SUM(J11:R11) -> 9289726 | J11: 9289726
A12: MPM Agencies | B12: 96900 | D12: =VLOOKUP(A12,$H$8:$I$17,2,0) -> 96900 | E12: =+B12-D12 -> 0 | G12: Nebu John | H12: Matha Agencies | I12: =SUM(J12:R12) -> 5070634 | J12: 1514350 | K12: 3556284
A13: Om Sai Ram | B13: 14565 | D13: =VLOOKUP(A13,$H$8:$I$17,2,0) -> 14565 | E13: =+B13-D13 -> 0 | G13: Nebu John | H13: MPM Agencies | I13: =SUM(J13:R13) -> 96900 | J13: 96900
A14: Quality Feeds | B14: 2430726 | D14: =VLOOKUP(A14,$H$8:$I$17,2,0) -> 2430726 | E14: =+B14-D14 -> 0 | G14: Nebu John | H14: Quality Feeds | I14: =SUM(J14:R14) -> 2430726 | J14: 2430726
A15: Rishan Exporters | B15: 3159329 | D15: =VLOOKUP(A15,$H$8:$I$17,2,0) -> 3159329 | E15: =+B15-D15 -> 0 | G15: Raja Kumar | H15: Rishan Exporters | I15: =SUM(J15:R15) -> 3159329 | J15: 3159329
A16: Royal Traders | B16: 475 | D16: =VLOOKUP(A16,$H$8:$I$17,2,0) -> 475 | E16: =+B16-D16 -> 0 | G16: Raja Kumar | H16: S I T Agencies | I16: =SUM(J16:R16) -> 2685011 | K16: 683100 | M16: 892375 | N16: 1109536
A17: S I T Agencies | B17: 2685011 | D17: =VLOOKUP(A17,$H$8:$I$17,2,0) -> 2685011 | E17: =+B17-D17 -> 0 | G17: Ranjith | H17: Om Sai Ram | I17: =SUM(J17:R17) -> 14565 | K17: 14565
A18: Grand Total | B18: =SUM(B8:B17) -> 26071153 | D18: =SUM(D8:D17) -> 26071153 | E18: =SUM(E8:E17) -> 0 | H18: Grand Total | I18: =SUM(I8:I17) -> 26071153 | J18: =SUM(J8:J17) -> 16921731 | K18: =SUM(K8:K17) -> 7147036.4 | L18: =SUM(L8:L17) -> 0 | M18: =SUM(M8:M17) -> 892850 | N18: =SUM(N8:N17) -> 1109536 | O18: =SUM(O8:O17) -> 0 | P18: =SUM(P8:P17) -> 0 | ... R18: =SUM(R8:R17) -> 0
A21: Suguna | B21: Debit | G21: ASM | H21: Suguna | I21: Pending Bills | J21: (< 15 days ) | K21: 15 to 30 days | L21: 30 to 45 days | M21: 45 to 60 days | N21: 60 to 90 days | O21: 90 to 180 days | P21: 180 to 365 days | Q21: 365 to 730 days | R21: (> 730 days )
A22: Bismillah Feeds | B22: 3013130 | D22: =VLOOKUP(A22,$H$22:$I$27,2,0) -> 3013130 | E22: =+B22-D22 -> 0 | G22: Nebu John | H22: Bismillah Feeds | I22: =SUM(J22:R22) -> 3013130 | J22: 572360 | K22: 2440770
A23: Jaya Kumar Poultry Farm | B23: 2738425 | D23: =VLOOKUP(A23,$H$22:$I$27,2,0) -> 2738425 | E23: =+B23-D23 -> 0 | G23: Nebu John | H23: J K Agencies | I23: =SUM(J23:R23) -> 1311295 | K23: =1327500-16205 -> 1311295
A24: J K Agencies | B24: 1311295 | D24: =VLOOKUP(A24,$H$22:$I$27,2,0) -> 1311295 | E24: =+B24-D24 -> 0 | G24: Nebu John | H24: M S Feeds | I24: =SUM(J24:R24) -> 3252785 | J24: 3252785
A25: M S Feeds | B25: 3252785 | D25: =VLOOKUP(A25,$H$22:$I$27,2,0) -> 3252785 | E25: =+B25-D25 -> 0 | G25: Nebu John | H25: Quality Feeds | I25: =SUM(J25:R25) -> 234300 | J25: 234300
A26: Quality Feeds | B26: 234300 | D26: =VLOOKUP(A26,$H$22:$I$27,2,0) -> 234300 | E26: =+B26-D26 -> 0 | G26: Raja Kumar | H26: Rishan Exporters | I26: =SUM(J26:R26) -> 3484675 | J26: 3484675
A27: Rishan Exporters | B27: 3484675 | D27: =VLOOKUP(A27,$H$22:$I$27,2,0) -> 3484675 | E27: =+B27-D27 -> 0 | G27: Ranjith | H27: Jaya Kumar Poultry Farm | I27: =SUM(J27:R27) -> 2738425 | J27: 2738425
A28: Grand Total | B28: =SUM(B22:B27) -> 14034610 | D28: =SUM(D22:D27) -> 14034610 | E28: =SUM(E22:E27) -> 0 | H28: Grand Total | I28: =SUM(I22:I27) -> 14034610 | J28: =SUM(J22:J27) -> 10282545 | K28: =SUM(K22:K27) -> 3752065 | S28: =+D28-I28 -> 0
A30: Erode | B30: Debit | G30: ASM | H30: Erode | I30: Pending Bills | J30: (< 15 days ) | K30: 15 to 30 days | L30: 30 to 45 days | M30: 45 to 60 days | N30: 60 to 90 days | O30: 90 to 180 days | P30: 180 to 365 days | Q30: 365 to 730 days | R30: (> 730 days )
A31: Kurikkal Chicken Wandoor | B31: 1874174 | D31: =+VLOOKUP(A31,$H$31:$I$34,2,0) -> 1874174 | E31: =+B31-D31 -> 0 | G31: Adarsh | H31: Ras Traders | I31: 190900 | M31: 190900
A32: Ras Traders | B32: 190900 | D32: =+VLOOKUP(A32,$H$31:$I$34,2,0) -> 190900 | E32: =+B32-D32 -> 0 | G32: Direct - Inactive | H32: Kurikkal Chicken Wandoor | I32: 1874174 | R32: 1874174
A33: Shakra Feeds & Hatcheries | B33: 985733 | D33: =+VLOOKUP(A33,$H$31:$I$34,2,0) -> 985733 | E33: =+B33-D33 -> 0 | G33: Raghavendra | H33: Shakra Feeds & Hatcheries | I33: 985733 | Q33: 985733
A34: S I T Agencies | B34: 832050 | D34: =+VLOOKUP(A34,$H$31:$I$34,2,0) -> 832050 | E34: =+B34-D34 -> 0 | G34: Raja Kumar | H34: S I T Agencies | I34: 832050 | M34: 668100 | O34: 163950
A35: Grand Total | B35: =SUM(B31:B34) -> 3882857 | D35: =SUM(D31:D34) -> 3882857 | E35: =SUM(E31:E34) -> 0 | H35: Grand Total | I35: 3882857 | M35: 859000 | O35: 163950 | Q35: 985733 | R35: 1874174
I37: =I35+I28+I18+I4 -> 45578192

Sheet TS
A1: Jamuna | B1: Debit | G1: ASM | H1: Jamuna | I1: Pending Bills | J1: (< 15 days ) | K1: 15 to 30 days | L1: 30 to 45 days | M1: 45 to 60 days | N1: 60 to 90 days | O1: 90 to 180 days | P1: 180 to 365 days | Q1: 365 to 730 days | R1: (> 730 days )
A2: Kishan poultry society | B2: 340 | D2: =VLOOKUP(A2,$H$2:$I$15,2,0) -> 340 | E2: =+B2-D2 -> 0 | G2: Ashok | H2: Lotus Enterprises | I2: =SUM(J2:R2) -> 5607262.2 | J2: 4005000 | K2: 1235900 | L2: 366362.15
A3: Lotus Enterprises | B3: 5607262.2 | D3: =VLOOKUP(A3,$H$2:$I$15,2,0) -> 5607262.2 | E3: =+B3-D3 -> 0 | G3: Ashok | H3: Shree Agencies | I3: =SUM(J3:R3) -> 5742269.8 | J3: 5742269.8
A4: Mallikharjuna Rao Poultry Farm | B4: 700 | D4: =VLOOKUP(A4,$H$2:$I$15,2,0) -> 700 | E4: =+B4-D4 -> 0 | G4: Ashok | H4: Snehith Reddy Poultry And Feeds | I4: =SUM(J4:R4) -> 812230.48 | J4: 812230.48
A5: M/s Excel Poultry | B5: 60000 | D5: =VLOOKUP(A5,$H$2:$I$15,2,0) -> 60000 | E5: =+B5-D5 -> 0 | G5: Bandaru Balaji | H5: Sri Parameshwari Broiler Poultry Farm & Feeds | I5: =SUM(J5:R5) -> 417103 | J5: 417103
A6: Narender Reddy poultry farms | B6: 5200 | D6: =VLOOKUP(A6,$H$2:$I$15,2,0) -> 5200 | E6: =+B6-D6 -> 0 | G6: G Chandra Sekhar | H6: Obulesh poultry Farm | I6: =SUM(J6:R6) -> 65500 | K6: 65500
A7: Obulesh poultry Farm | B7: 65500 | D7: =VLOOKUP(A7,$H$2:$I$15,2,0) -> 65500 | E7: =+B7-D7 -> 0 | G7: G Chandra Sekhar | H7: Sri Laxmi Narasimha Poultry Farms | I7: =SUM(J7:R7) -> 500 | K7: 500
A8: Shree Agencies | B8: 5742269.8 | D8: =VLOOKUP(A8,$H$2:$I$15,2,0) -> 5742269.8 | E8: =+B8-D8 -> 0 | G8: G Chandra Sekhar | H8: T Nadipi Gurrappa | I8: =SUM(J8:R8) -> 100309 | J8: 100309
A9: Snehith Reddy Poultry And Feeds | B9: 812230.48 | D9: =VLOOKUP(A9,$H$2:$I$15,2,0) -> 812230.48 | E9: =+B9-D9 -> 0 | G9: Karre Narasimha | H9: Kishan poultry society | I9: =SUM(J9:R9) -> 340 | J9: 340
A10: Sri Devi Poutry Farm, Narasaraopete | B10: 1582237.2 | D10: =VLOOKUP(A10,$H$2:$I$15,2,0) -> 1582237.2 | E10: =+B10-D10 -> 0 | G10: Karre Narasimha | H10: Mallikharjuna Rao Poultry Farm | I10: =SUM(J10:R10) -> 700 | O10: 700
A11: Sri Laxmi Narasimha Poultry Farms | B11: 500 | D11: =VLOOKUP(A11,$H$2:$I$15,2,0) -> 500 | E11: =+B11-D11 -> 0 | G11: Karre Narasimha | H11: Narender Reddy poultry farms | I11: =SUM(J11:R11) -> 5200 | K11: 5200
A12: Sri Parameshwari Broiler Poultry Farm & Feeds | B12: 417103 | D12: =VLOOKUP(A12,$H$2:$I$15,2,0) -> 417103 | E12: =+B12-D12 -> 0 | G12: N. Srinivas | H12: M/s Excel Poultry | I12: =SUM(J12:R12) -> 60000 | K12: 60000
A13: Sri sreshta Poultries and feed | B13: 709.98 | D13: =VLOOKUP(A13,$H$2:$I$15,2,0) -> 709.98 | E13: =+B13-D13 -> 0 | G13: N. Srinivas | H13: Sri sreshta Poultries and feed | I13: =SUM(J13:R13) -> 709.98 | O13: 709.98
A14: T Nadipi Gurrappa | B14: 100309 | D14: =VLOOKUP(A14,$H$2:$I$15,2,0) -> 100309 | E14: =+B14-D14 -> 0 | G14: N. Srinivas | H14: Vignan Organics | I14: =SUM(J14:R14) -> 24976.91 | J14: 24976.91
A15: Vignan Organics | B15: 24976.91 | D15: =VLOOKUP(A15,$H$2:$I$15,2,0) -> 24976.91 | E15: =+B15-D15 -> 0 | G15: Seetharam | H15: Sri Devi Poutry Farm, Narasaraopete | I15: =SUM(J15:R15) -> 1582237.2 | J15: 1582237.2
A16: Grand Total | B16: =SUM(B2:B15) -> 14419338 | D16: =SUM(D2:D15) -> 14419338 | E16: =SUM(E2:E15) -> 0 | H16: Grand Total | I16: =SUM(I2:I15) -> 14419338 | J16: =SUM(J2:J15) -> 12684466 | K16: =SUM(K2:K15) -> 1367100 | L16: =SUM(L2:L15) -> 366362.15 | M16: =SUM(M2:M15) -> 0 | N16: =SUM(N2:N15) -> 0 | O16: =SUM(O2:O15) -> 1409.98 | P16: =SUM(P2:P15) -> 0 | ... R16: =SUM(R2:R15) -> 0 | S16: =SUM(J16:R16) -> 14419339 | T16: =+I16-S16 -> 0
B17: 13747381 | C17: =+B16-B17 -> 671957.6 | D17: =+B16-D16 -> 0
A19: Noveltech | B19: Debit | G19: ASM | H19: Noveltech | I19: Pending Bills | J19: (< 15 days ) | K19: 15 to 30 days | L19: 30 to 45 days | M19: 45 to 60 days | N19: 60 to 90 days | O19: 90 to 180 days | P19: 180 to 365 days | Q19: 365 to 730 days
A20: K P R fresh products | B20: 72657.64 | D20: =VLOOKUP(A20,$H$20:$I$22,2,0) -> 72657.64 | E20: =+B20-D20 -> 0 | G20: Karre Narasimha | H20: K P R fresh products | I20: =SUM(J20:R20) -> 72657.64 | Q20: 72657.64
A21: Laxmi Sai Breeding Farms Pvt Ltd | B21: 725 | D21: =VLOOKUP(A21,$H$20:$I$22,2,0) -> 725 | E21: =+B21-D21 -> 0 | G21: Karre Narasimha | H21: Laxmi Sai Breeding Farms Pvt Ltd | I21: =SUM(J21:R21) -> 725 | P21: 725
A22: Masthan Poultry Farms | B22: 198547.2 | D22: =VLOOKUP(A22,$H$20:$I$22,2,0) -> 198547.2 | E22: =+B22-D22 -> 0 | G22: N. Srinivas | H22: Masthan Poultry Farms | I22: =SUM(J22:R22) -> 198547.2 | P22: 198547.2
A23: Grand Total | B23: =SUM(B20:B22) -> 271929.84 | D23: =SUM(D20:D22) -> 271929.84 | E23: =SUM(E20:E22) -> 0 | H23: Grand Total | I23: =SUM(I20:I22) -> 271929.84 | J23: =SUM(J20:J22) -> 0 | K23: =SUM(K20:K22) -> 0 | L23: =SUM(L20:L22) -> 0 | M23: =SUM(M20:M22) -> 0 | N23: =SUM(N20:N22) -> 0 | O23: =SUM(O20:O22) -> 0 | P23: =SUM(P20:P22) -> 199272.2 | ... R23: =SUM(R20:R22) -> 0

Sheet VJD
A1: VJD | B1: Debit | G1: ASM | H1: VJD | I1: Pending Bills | J1: (< 15 days ) | K1: 15 to 30 days | L1: 30 to 45 days | M1: 45 to 60 days | N1: 60 to 90 days | O1: 90 to 180 days | P1: 180 to 365 days | Q1: 365 to 730 days | R1: (> 730 days )
A2: A1 Fresh Chicken & Poultry Centre _x000D_ | B2: 299887.15 | D2: =VLOOKUP(A2,$H$2:$I$43,2,0) -> 299887.15 | E2: =B2-D2 -> 0 | G2: Bandaru Balaji | H2: Dhanalakshmi poultry farm | I2: =SUM(J2:R2) -> 319.65 | J2: 319.65
A3: Aarna Traders | B3: 82308.51 | D3: =VLOOKUP(A3,$H$2:$I$43,2,0) -> 82308.51 | E3: =B3-D3 -> 0 | G3: Bandaru Balaji | H3: Sri Parameshwari Broiler Poultry Farm & Feeds | I3: =SUM(J3:R3) -> 496246.81 | J3: 496246.81
A4: Abhayanjaneya Poultry Trader's | B4: 2991683 | D4: =VLOOKUP(A4,$H$2:$I$43,2,0) -> 2991683 | E4: =B4-D4 -> 0 | G4: Direct - Inactive | H4: Abhinay Reddy Poultry Farm | I4: =SUM(J4:R4) -> 170371 | R4: 170371
A5: Abhinay Reddy Poultry Farm | B5: 170371 | D5: =VLOOKUP(A5,$H$2:$I$43,2,0) -> 170371 | E5: =B5-D5 -> 0 | G5: Direct - Inactive | H5: Ambarish Poultry Farm | I5: =SUM(J5:R5) -> 149739 | R5: 149739
A6: Ambarish Poultry Farm | B6: 149739 | D6: =VLOOKUP(A6,$H$2:$I$43,2,0) -> 149739 | E6: =B6-D6 -> 0 | G6: Direct - Inactive | H6: Anjali Enterprises | I6: =SUM(J6:R6) -> 305642.81 | R6: 305642.81
A7: Anjali Enterprises | B7: 305642.81 | D7: =VLOOKUP(A7,$H$2:$I$43,2,0) -> 305642.81 | E7: =B7-D7 -> 0 | G7: Direct - Inactive | H7: Green Valley Nutrition_x000D_ | I7: =SUM(J7:R7) -> 261320 | R7: 261320
A8: Devi Prasuna Poultry Farm | B8: 347424.28 | D8: =VLOOKUP(A8,$H$2:$I$43,2,0) -> 347424.28 | E8: =B8-D8 -> 0 | G8: Direct - Inactive | H8: K Satya Padma Latha | I8: =SUM(J8:R8) -> 117261 | R8: 117261
A9: Dhanalakshmi poultry farm | B9: 319.65 | D9: =VLOOKUP(A9,$H$2:$I$43,2,0) -> 319.65 | E9: =B9-D9 -> 0 | G9: Direct - Inactive | H9: Lakshmi Narasimhaswamy Poultry Farm | I9: =SUM(J9:R9) -> 40369 | R9: 40369
A10: Green Valley Nutrition_x000D_ | B10: 261320 | D10: =VLOOKUP(A10,$H$2:$I$43,2,0) -> 261320 | E10: =B10-D10 -> 0 | G10: Direct - Inactive | H10: Siva Sai Enterprises_x000D_ | I10: =SUM(J10:R10) -> 106034.36 | R10: 106034.36
A11: Honey Poultry Feeds_x000D_ | B11: 877923 | D11: =VLOOKUP(A11,$H$2:$I$43,2,0) -> 877923 | E11: =B11-D11 -> 0 | G11: G Chandra Sekhar | H11: Srinivasulareddy palakolanu | I11: =SUM(J11:R11) -> 10000 | J11: 10000
A12: K.R.Traders _x000D_ | B12: 157024.79 | D12: =VLOOKUP(A12,$H$2:$I$43,2,0) -> 157024.79 | E12: =B12-D12 -> 0 | G12: G Chandra Sekhar | H12: Umamaheshwara Poultry Farm | I12: =SUM(J12:R12) -> 15925 | K12: 15925
A13: K Satya Padma Latha | B13: 117261 | D13: =VLOOKUP(A13,$H$2:$I$43,2,0) -> 117261 | E13: =B13-D13 -> 0 | G13: Gouse | H13: Aarna Traders | I13: =SUM(J13:R13) -> 82308.51 | Q13: 82308.51
A14: K V R Poultry Farm | B14: 202127 | D14: =VLOOKUP(A14,$H$2:$I$43,2,0) -> 202127 | E14: =B14-D14 -> 0 | G14: Gouse | H14: Devi Prasuna Poultry Farm | I14: =SUM(J14:R14) -> 347424.28 | R14: 347424.28
A15: Lakshmi Narasimhaswamy Poultry Farm | B15: 40369 | D15: =VLOOKUP(A15,$H$2:$I$43,2,0) -> 40369 | E15: =B15-D15 -> 0 | G15: Gouse | H15: K V R Poultry Farm | I15: =SUM(J15:R15) -> 202127 | R15: 202127
A16: Lakshmi Poultry, Vadluru | B16: 35337.16 | D16: =VLOOKUP(A16,$H$2:$I$43,2,0) -> 35337.16 | E16: =B16-D16 -> 0 | G16: Gouse | H16: Lakshmi Poultry, Vadluru | I16: =SUM(J16:R16) -> 35337.16 | J16: 35337.16
A17: M Janaki Surya Narayana Raju | B17: 1277286.7 | D17: =VLOOKUP(A17,$H$2:$I$43,2,0) -> 1277286.7 | E17: =B17-D17 -> 0 | G17: Gouse | H17: M Janaki Surya Narayana Raju | I17: =SUM(J17:R17) -> 1277286.7 | J17: 863277.11 | N17: 363087.7 | P17: 50921.93
A18: MNVSN Raju Poultry Farm | B18: 775240.52 | D18: =VLOOKUP(A18,$H$2:$I$43,2,0) -> 775240.52 | E18: =B18-D18 -> 0 | G18: Gouse | H18: MNVSN Raju Poultry Farm | I18: =SUM(J18:R18) -> 775240.52 | K18: 775240.52
A19: M Sathyavathi | B19: 480720.83 | D19: =VLOOKUP(A19,$H$2:$I$43,2,0) -> 480720.83 | E19: =B19-D19 -> 0 | G19: Gouse | H19: M Sathyavathi | I19: =SUM(J19:R19) -> 480720.83 | L19: 480720.83
A20: Nalini Poultry Farm_x000D_ | B20: 234437 | D20: =VLOOKUP(A20,$H$2:$I$43,2,0) -> 234437 | E20: =B20-D20 -> 0 | G20: Gouse | H20: Poorna Chandra Poultry Farm | I20: =SUM(J20:R20) -> 613527.79 | M20: 155541.9 | O20: 457985.89
A21: NNR Associates _x000D_ | B21: 891238.03 | D21: =VLOOKUP(A21,$H$2:$I$43,2,0) -> 891238.03 | E21: =B21-D21 -> 0 | G21: Gouse | H21: RKR Poultry Farm | I21: =SUM(J21:R21) -> 343860 | R21: 343860
A22: Poorna Chandra Poultry Farm | B22: 613527.79 | D22: =VLOOKUP(A22,$H$2:$I$43,2,0) -> 613527.79 | E22: =B22-D22 -> 0 | G22: Gouse | H22: S D Reshma poultry farm | I22: =SUM(J22:R22) -> 5845.23 | Q22: 5845.23
A23: RKR Poultry Farm | B23: 343860 | D23: =VLOOKUP(A23,$H$2:$I$43,2,0) -> 343860 | E23: =B23-D23 -> 0 | G23: Gouse | H23: Simhadri Srinivasa Rao _x000D_ | I23: =SUM(J23:R23) -> 650299 | R23: 650299
A24: Sai Poultries | B24: 1881315 | D24: =VLOOKUP(A24,$H$2:$I$43,2,0) -> 1881315 | E24: =B24-D24 -> 0 | G24: Gouse | H24: Siva Rama Poultry Farm | I24: =SUM(J24:R24) -> 199836 | R24: 199836
A25: S D Reshma poultry farm | B25: 5845.23 | D25: =VLOOKUP(A25,$H$2:$I$43,2,0) -> 5845.23 | E25: =B25-D25 -> 0 | G25: Gouse | H25: Sri Lakshmi Panduranga Poultry Farm | I25: =SUM(J25:R25) -> 820928.73 | J25: 544839.36 | L25: 276089.37
A26: Simhadri Srinivasa Rao _x000D_ | B26: 650299 | D26: =VLOOKUP(A26,$H$2:$I$43,2,0) -> 650299 | E26: =B26-D26 -> 0 | G26: Gouse | H26: Sri Lakshmi Srinivasa Poultries | I26: =SUM(J26:R26) -> 21945.42 | P26: 21945.42
A27: Siva Poultries | B27: 1842785 | D27: =VLOOKUP(A27,$H$2:$I$43,2,0) -> 1842785 | E27: =B27-D27 -> 0 | G27: Gouse | H27: S V J Poultry Farm | I27: =SUM(J27:R27) -> 313324.14 | Q27: 313324.14
A28: Siva Rama Poultry Farm | B28: 199836 | D28: =VLOOKUP(A28,$H$2:$I$43,2,0) -> 199836 | E28: =B28-D28 -> 0 | G28: Gouse | H28: V Krishnam Raju Poultries | I28: =SUM(J28:R28) -> 211742.63 | L28: 182479.2 | P28: 29263.43
A29: Siva Sai Enterprises_x000D_ | B29: 106034.36 | D29: =VLOOKUP(A29,$H$2:$I$43,2,0) -> 106034.36 | E29: =B29-D29 -> 0 | G29: Gouse | H29: VVS Muralidhara Poultry Farm | I29: =SUM(J29:R29) -> 25048 | R29: 25048
A30: Sri Devi Poutry Farm, Narasaraopete | B30: 1403517.6 | D30: =VLOOKUP(A30,$H$2:$I$43,2,0) -> 1403517.6 | E30: =B30-D30 -> 0 | G30: Ravibabu | H30: A1 Fresh Chicken & Poultry Centre _x000D_ | I30: =SUM(J30:R30) -> 299887.15 | R30: 299887.15
A31: Sri Lakshmi Panduranga Poultry Farm | B31: 820928.73 | D31: =VLOOKUP(A31,$H$2:$I$43,2,0) -> 820928.73 | E31: =B31-D31 -> 0 | G31: Ravibabu | H31: Honey Poultry Feeds_x000D_ | I31: =SUM(J31:R31) -> 877923 | R31: 877923
A32: Sri Lakshmi Srinivasa Poultries | B32: 21945.42 | D32: =VLOOKUP(A32,$H$2:$I$43,2,0) -> 21945.42 | E32: =B32-D32 -> 0 | G32: Ravibabu | H32: K.R.Traders _x000D_ | I32: =SUM(J32:R32) -> 157024.79 | R32: 157024.79
A33: Srinivasa Poultry Farm, Chandrala | B33: 458504 | D33: =VLOOKUP(A33,$H$2:$I$43,2,0) -> 458504 | E33: =B33-D33 -> 0 | G33: Ravibabu | H33: Nalini Poultry Farm_x000D_ | I33: =SUM(J33:R33) -> 234437 | R33: 234437
A34: Srinivasulareddy palakolanu | B34: 10000 | D34: =VLOOKUP(A34,$H$2:$I$43,2,0) -> 10000 | E34: =B34-D34 -> 0 | G34: Ravibabu | H34: NNR Associates _x000D_ | I34: =SUM(J34:R34) -> 891238.03 | R34: 891238.03
A35: Sri Parameshwari Broiler Poultry Farm & Feeds | B35: 496246.81 | D35: =VLOOKUP(A35,$H$2:$I$43,2,0) -> 496246.81 | E35: =B35-D35 -> 0 | G35: Ravibabu | H35: Srinivasa Poultry Farm, Chandrala | I35: =SUM(J35:R35) -> 458504 | R35: 458504
A36: Sri Sai Ram Poultry Feeds_x000D_ | B36: 647718 | D36: =VLOOKUP(A36,$H$2:$I$43,2,0) -> 647718 | E36: =B36-D36 -> 0 | G36: Ravibabu | H36: Sri Sai Ram Poultry Feeds_x000D_ | I36: =SUM(J36:R36) -> 647718 | R36: 647718
A37: S V J Poultry Farm | B37: 313324.14 | D37: =VLOOKUP(A37,$H$2:$I$43,2,0) -> 313324.14 | E37: =B37-D37 -> 0 | G37: Ravibabu | H37: T.Vasu Poultry Farm_x000D_ | I37: =SUM(J37:R37) -> 34317 | R37: 34317
A38: T.Vasu Poultry Farm_x000D_ | B38: 34317 | D38: =VLOOKUP(A38,$H$2:$I$43,2,0) -> 34317 | E38: =B38-D38 -> 0 | G38: Ravibabu | H38: Y Ranjth Kumar Poultry Farm | I38: =SUM(J38:R38) -> 12860.52 | Q38: 12860.52
A39: Umamaheshwara Poultry Farm | B39: 15925 | D39: =VLOOKUP(A39,$H$2:$I$43,2,0) -> 15925 | E39: =B39-D39 -> 0 | G39: Seetharam | H39: Abhayanjaneya Poultry Trader's | I39: =SUM(J39:R39) -> 2991683 | J39: 2991683
A40: Venkateswara Rao Poultry Farm | B40: 1468223 | D40: =VLOOKUP(A40,$H$2:$I$43,2,0) -> 1468223 | E40: =B40-D40 -> 0 | G40: Seetharam | H40: Sai Poultries | I40: =SUM(J40:R40) -> 1881315 | J40: 436000 | M40: 764500 | N40: 480150 | P40: 200665
...

Sheet Summary
A1: Sundry Debtors as of 31st July 2026
A2: ASM Name | B2: Sum of Pending Bills | C2: Sum of (< 15 days ) | D2: Sum of 15 to 30 days | E2: Sum of 30 to 45 days | F2: Sum of 45 to 60 days | G2: Sum of 60 to 90 days | H2: Sum of 90 to 180 days | I2: Sum of 180 to 365 days | J2: Sum of 365 to 730 days | K2: Sum of (> 730 days )
A3: Adarsh | B3: 622075 | C3: 430700 | D3: 0 | E3: 0 | F3: 191375 | G3: 0 | H3: 0 | I3: 0 | J3: 0 | K3: 0
A4: Ashok | B4: 12026762 | C4: 10559500 | D4: 1235900 | E4: 231362.15 | F4: 0 | G4: 0 | H4: 0 | I4: 0 | J4: 0 | K4: 0
A5: Bandaru Balaji | B5: 913669.46 | C5: 913669.46 | D5: 0 | E5: 0 | F5: 0 | G5: 0 | H5: 0 | I5: 0 | J5: 0 | K5: 0
A6: Dayananda | B6: 64450 | C6: 0 | D6: 0 | E6: 0 | F6: 0 | G6: 64450 | H6: 0 | I6: 0 | J6: 0 | K6: 0
A7: Direct - Active | B7: 16257522 | C7: 1616573 | D7: 2811956 | E7: 2308600 | F7: 1472565 | G7: 3198507 | H7: 3433392.8 | I7: 1379373.5 | J7: 2600 | K7: 33955
A8: Direct - Inactive | B8: 48756389 | C8: 0 | D8: 0 | E8: 0 | F8: 0 | G8: 0 | H8: 297680 | I8: 1078159 | J8: 1621800.2 | K8: 45758750
A9: DR | B9: 95 | C9: 95 | D9: 0 | E9: 0 | F9: 0 | G9: 0 | H9: 0 | I9: 0 | J9: 0 | K9: 0
A10: G Chandra Sekhar | B10: 255041 | C10: 144916 | D10: 81925 | E10: 0 | F10: 0 | G10: 0 | H10: 28200 | I10: 0 | J10: 0 | K10: 0
A11: Gouse | B11: 6406802 | C11: 1443453.6 | D11: 775240.52 | E11: 939289.4 | F11: 155541.9 | G11: 363087.7 | H11: 457985.89 | I11: 102130.78 | J11: 401477.88 | K11: 1768594.3
A12: Karre Narasimha | B12: 78897.64 | C12: 340 | D12: 5200 | E12: 0 | F12: 0 | G12: 0 | H12: 700 | I12: 0 | J12: 72657.64 | K12: 0
A13: Lavanya | B13: 1658447 | C13: 1658447 | D13: 0 | E13: 0 | F13: 0 | G13: 0 | H13: 0 | I13: 0 | J13: 0 | K13: 0
A14: Mahendra | B14: 5052371.2 | C14: 1659000 | D14: 5950 | E14: 80925 | F14: 0 | G14: 0 | H14: 468450 | I14: 1196972.2 | J14: 1125550 | K14: 515524
... A22: Seetharam | B22: 11169761 | C22: 5547199.6 | D22: 866238.15 | E22: 0 | F22: 764500 | G22: 480150 | H22: 0 | I22: 2043450 | J22: 1468223 | K22: 0
A23: (blank)
A24: Grand Total | B24: 1.5738144e+08 | C24: 51858577 | D24: 16741511 | E24: 3560176.5 | F24: 4144456.9 | G24: 5215730.7 | H24: 4851068.7 | I24: 5998632.8 | J24: 7934745.4 | K24: 57076538

Sheet Bal Conf
A1: Adarsh | B1: SD Ageing Report as of 31/07/2026 | D1: Bal Conf Status
A2: Particulars | B2: Pending Bills | D2: Received on | E2: Mode
A3: Haritha Agencies | B3: 430700
A4: Ras Traders | B4: 190900 | D4: 46256 | E4: Mail
A5: Total | B5: =SUBTOTAL(109,Table2[Pending Bills]) -> 622075
A7: Nebu John | B7: SD Ageing Report as of 31/07/2026
A8: Particulars | B8: Pending Bills
A9: Bismillah Feeds | B9: 3013130
A10: Bismillah Feeds | B10: 2893087.4 | D10: 46256 | E10: Whats App
A11: J K Agencies | B11: 1311295
A12: J K Agencies | B12: 9289726
A13: M S Feeds | B13: 3252785 | D13: 46256 | E13: Whats App
A14: Matha Agencies | B14: 5070634
A15: MPM Agencies | B15: 96900
A16: Quality Feeds | B16: 234300 | D16: 46256 | E16: Mail
A17: Quality Feeds | B17: 2430726 | D17: 46256 | E17: Mail
A18: Total | B18: =SUBTOTAL(109,B9:B17) -> 27592583
A20: Raja Kumar | B20: SD Ageing Report as of 31/07/2026
A21: Particulars | B21: Pending Bills
A22: Rishan Exporters | B22: 3484675 | D22: 46256 | E22: Mail
A23: Rishan Exporters | B23: 3159329 | D23: 46256 | E23: Mail
A24: S I T Agencies | B24: 832050 | D24: 46256 | E24: Mail
A25: S I T Agencies | B25: 2685011 | D25: 46256 | E25: Mail
A26: Total | B26: =SUBTOTAL(109,B22:B25) -> 10161065
A28: Grand Total | B28: =+B26+B18+Table2[[#Totals],[Pending Bills]] -> 38375723
A30: Ashok | B30: SD Ageing Report as of 31/07/2026
A31: Particulars | B31: Pending Bills
A32: Lotus Enterprises | B32: 5472262.2
A33: Shree Agencies | B33: 5742269.8
A34: Snehith Reddy Poultry And Feeds | B34: 812230.48
A35: Total | B35: =SUM(B32:B34) -> 12026762
A37: Bandaru Balaji | B37: SD Ageing Report as of 31/07/2026
A38: Particulars | B38: Pending Bills
A39: Dhanalakshmi poultry farm | B39: 319.65
A40: Sri Parameshwari Broiler Poultry Farm & Feeds | B40: 496246.81 | D40: 46247 | E40: Hard Copy
A41: Sri Parameshwari Broiler Poultry Farm & Feeds | B41: 417103 | D41: 46247 | E41: Hard Copy
A42: Total | B42: 913669.46
A44: Karre Narasimha | B44: SD Ageing Report as of 31/07/2026
A45: Particulars | B45: Pending Bills
A46: K P R fresh products | B46: 72657.64
...

Sheet Consolidated
A1: ASM | B1: Particulars | C1: Pending Bills | D1: (< 15 days ) | E1: 15 to 30 days | F1: 30 to 45 days | G1: 45 to 60 days | H1: 60 to 90 days | I1: 90 to 180 days | J1: 180 to 365 days | K1: 365 to 730 days | L1: (> 730 days ) | N1: Row Labels | O1: Sum of Pending Bills | Q1: Amount
A2: =KA!G2 -> Direct - Active | B2: =KA!H2 -> Chowdayya Poultry Farms Malavalli | C2: =KA!I2 -> 13625 | D2: =KA!J2 -> 0 | E2: =KA!K2 -> 0 | F2: =KA!L2 -> 0 | G2: =KA!M2 -> 0 | H2: =KA!N2 -> 13625 | ... L2: =KA!R2 -> 0 | N2: A1 Fresh Chicken & Poultry Centre _x000D_ | O2: 299887.15
A3: =KA!G3 -> Direct - Active | B3: =KA!H3 -> G.P.P.Poultry Farm | C3: =KA!I3 -> 4307350 | D3: =KA!J3 -> 912190 | E3: =KA!K3 -> 1141200 | F3: =KA!L3 -> 900410 | G3: =KA!M3 -> 686000 | H3: =KA!N3 -> 667550 | ... L3: =KA!R3 -> 0 | N3: Aarna Traders | O3: 82308.51
A4: =KA!G4 -> Direct - Active | B4: =KA!H4 -> Javare Gowda Dairy Farm | C4: =KA!I4 -> 8815 | D4: =KA!J4 -> 0 | E4: =KA!K4 -> 0 | F4: =KA!L4 -> 0 | G4: =KA!M4 -> 0 | H4: =KA!N4 -> 3320 | ... L4: =KA!R4 -> 0 | N4: Aavion Enterprises Drs | O4: 59400
A5: =KA!G5 -> Direct - Active | B5: =KA!H5 -> Jogi Gowda Poultry Farm | C5: =KA!I5 -> 86330 | D5: =KA!J5 -> 27230 | E5: =KA!K5 -> 59100 | F5: =KA!L5 -> 0 | G5: =KA!M5 -> 0 | H5: =KA!N5 -> 0 | ... L5: =KA!R5 -> 0 | N5: Abhayanjaneya Poultry Trader's | O5: 2991683
A6: =KA!G6 -> Direct - Active | B6: =KA!H6 -> K G Satya Poultry Farm | C6: =KA!I6 -> 367278 | D6: =KA!J6 -> 183088 | E6: =KA!K6 -> 95800 | F6: =KA!L6 -> 0 | G6: =KA!M6 -> 88390 | H6: =KA!N6 -> 0 | ... L6: =KA!R6 -> 0 | N6: Abhinay Reddy Poultry Farm | O6: 170371
A7: =KA!G7 -> Direct - Active | B7: =KA!H7 -> Krishna Poultry Farm | C7: =KA!I7 -> 2754944.5 | D7: =KA!J7 -> 0 | E7: =KA!K7 -> 225100 | F7: =KA!L7 -> 0 | G7: =KA!M7 -> 186650 | H7: =KA!N7 -> 174300 | ... L7: =KA!R7 -> 0 | N7: Abhishek Poultry Farm K Shetthali | O7: 30300
A8: =KA!G8 -> Direct - Active | B8: =KA!H8 -> Kumar Poultry Farm | C8: =KA!I8 -> 1025 | D8: =KA!J8 -> 0 | E8: =KA!K8 -> 0 | F8: =KA!L8 -> 0 | G8: =KA!M8 -> 0 | H8: =KA!N8 -> 0 | ... L8: =KA!R8 -> 0 | N8: Ajwa Poultry Feed | O8: 121200
A9: =KA!G9 -> Direct - Active | B9: =KA!H9 -> Muralidhar Poultry Farm | C9: =KA!I9 -> 55445 | D9: =KA!J9 -> 55445 | E9: =KA!K9 -> 0 | F9: =KA!L9 -> 0 | G9: =KA!M9 -> 0 | H9: =KA!N9 -> 0 | ... L9: =KA!R9 -> 0 | N9: Akash Enterprises | O9: 1635149.8
A10: =KA!G10 -> Direct - Active | B10: =KA!H10 -> Nandish Poultry Farm Mandya | C10: =KA!I10 -> 3950 | D10: =KA!J10 -> 0 | E10: =KA!K10 -> 0 | F10: =KA!L10 -> 0 | G10: =KA!M10 -> 3950 | H10: =KA!N10 -> 0 | ... L10: =KA!R10 -> 0 | N10: Akash Pig Farm | O10: 6570
A11: =KA!G11 -> Direct - Active | B11: =KA!H11 -> Poonacha PB | C11: =KA!I11 -> 31300 | D11: =KA!J11 -> 0 | E11: =KA!K11 -> 0 | F11: =KA!L11 -> 31300 | G11: =KA!M11 -> 0 | H11: =KA!N11 -> 0 | ... L11: =KA!R11 -> 0 | N11: Ambarish Poultry Farm | O11: 149739
A12: =KA!G12 -> Direct - Active | B12: =KA!H12 -> Prasanan Kumar Poultry Farm | C12: =KA!I12 -> 1280 | D12: =KA!J12 -> 0 | E12: =KA!K12 -> 0 | F12: =KA!L12 -> 0 | G12: =KA!M12 -> 0 | H12: =KA!N12 -> 0 | ... L12: =KA!R12 -> 0 | N12: Ambika Poultry Farm | O12: 236276.25
A13: =KA!G13 -> Direct - Active | B13: =KA!H13 -> Prasanna Pig Farm | C13: =KA!I13 -> 180 | D13: =KA!J13 -> 0 | E13: =KA!K13 -> 180 | F13: =KA!L13 -> 0 | G13: =KA!M13 -> 0 | H13: =KA!N13 -> 0 | ... L13: =KA!R13 -> 0 | N13: Amol Pig Farm | O13: 104690
... A33: =KA!G33 -> Direct - Inactive | B33: =KA!H33 -> Amol Pig Farm | C33: =KA!I33 -> 104690 | D33: =KA!J33 -> 0 | E33: =KA!K33 -> 0 | F33: =KA!L33 -> 0 | G33: =KA!M33 -> 0 | H33: =KA!N33 -> 0 | ... L33: =KA!R33 -> 28450 | N33: G.P.P.Poultry Farm | O33: 4307350
A34: =KA!G34 -> Direct - Inactive | B34: =KA!H34 -> Ananya Poultry Farm & Supplies | C34: =KA!I34 -> 54000 | D34: =KA!J34 -> 0 | E34: =KA!K34 -> 0 | F34: =KA!L34 -> 0 | G34: =KA!M34 -> 0 | H34: =KA!N34 -> 0 | ... L34: =KA!R34 -> 54000 | N34: GMI Poultry Foods | O34: 125036 | Q34: =VLOOKUP(N34,'SD with Cr bal'!$D$3:$E$99,2,0) -> 90000
A35: =KA!G35 -> Direct - Inactive | B35: =KA!H35 -> Ashok Poultry Farm_x000D_ | C35: =KA!I35 -> 599850 | D35: =KA!J35 -> 0 | E35: =KA!K35 -> 0 | F35: =KA!L35 -> 0 | G35: =KA!M35 -> 0 | H35: =KA!N35 -> 0 | ... L35: =KA!R35 -> 599850 | N35: Green Valley Nutrition_x000D_ | O35: 261320
A36: =KA!G36 -> Direct - Inactive | B36: =KA!H36 -> Associate Professor Dept.of ILFC Dairy | C36: =KA!I36 -> 8911 | D36: =KA!J36 -> 0 | E36: =KA!K36 -> 0 | F36: =KA!L36 -> 0 | G36: =KA!M36 -> 0 | H36: =KA!N36 -> 0 | ... L36: =KA!R36 -> 8911 | N36: Gurunatha Poultry Farm | O36: 900848
A37: =KA!G37 -> Direct - Inactive | B37: =KA!H37 -> Bandipura Breeders, Mysore | C37: =KA!I37 -> 933158 | D37: =KA!J37 -> 0 | E37: =KA!K37 -> 0 | F37: =KA!L37 -> 0 | G37: =KA!M37 -> 0 | H37: =KA!N37 -> 0 | ... L37: =KA!R37 -> 933158 | N37: Hanumanthappa Poultry Farm | O37: 180414
A38: =KA!G38 -> Direct - Inactive | B38: =KA!H38 -> BJS Poultry Farm | C38: =KA!I38 -> 306533 | D38: =KA!J38 -> 0 | E38: =KA!K38 -> 0 | F38: =KA!L38 -> 0 | G38: =KA!M38 -> 0 | H38: =KA!N38 -> 0 | ... L38: =KA!R38 -> 306533 | N38: Happy Chicken Centre | O38: 1341583
A39: =KA!G39 -> Direct - Inactive | B39: =KA!H39 -> Chaluvaraya Swamy Poultry Farm,Channapatna | C39: =KA!I39 -> 183720 | D39: =KA!J39 -> 0 | E39: =KA!K39 -> 0 | F39: =KA!L39 -> 0 | G39: =KA!M39 -> 0 | H39: =KA!N39 -> 0 | ... L39: =KA!R39 -> 183720 | N39: Happy Feed & Farms LLP | O39: 21500
A40: =KA!G40 -> Direct - Inactive | B40: =KA!H40 -> Deeksha Vet Medicals | C40: =KA!I40 -> 52000 | D40: =KA!J40 -> 0 | E40: =KA!K40 -> 0 | F40: =KA!L40 -> 0 | G40: =KA!M40 -> 0 | H40: =KA!N40 -> 0 | ... L40: =KA!R40 -> 0 | N40: Harish Poultry Farm- Mandya | O40: 13280
A41: =KA!G41 -> Direct - Inactive | B41: =KA!H41 -> Devapriya Foods & Feeds,Honnavara | C41: =KA!I41 -> 511820 | D41: =KA!J41 -> 0 | E41: =KA!K41 -> 0 | F41: =KA!L41 -> 0 | G41: =KA!M41 -> 0 | H41: =KA!N41 -> 0 | ... L41: =KA!R41 -> 511820 | N41: Haritha Agencies | O41: 430700
A42: =KA!G42 -> Direct - Inactive | B42: =KA!H42 -> Devaraja Poultry Farm | C42: =KA!I42 -> 461812 | D42: =KA!J42 -> 0 | E42: =KA!K42 -> 0 | F42: =KA!L42 -> 0 | G42: =KA!M42 -> 0 | H42: =KA!N42 -> 0 | ... L42: =KA!R42 -> 461812 | N42: Harsha Poultry Farm | O42: 8400
A43: =KA!G43 -> Direct - Inactive | B43: =KA!H43 -> Gurunatha Poultry Farm | C43: =KA!I43 -> 900848 | D43: =KA!J43 -> 0 | E43: =KA!K43 -> 0 | F43: =KA!L43 -> 0 | G43: =KA!M43 -> 0 | H43: =KA!N43 -> 0 | ... L43: =KA!R43 -> 900848 | N43: HKGN Poultry Farm | O43: 24074
A44: =KA!G44 -> Direct - Inactive | B44: =KA!H44 -> Happy Chicken Centre | C44: =KA!I44 -> 1341583 | D44: =KA!J44 -> 0 | E44: =KA!K44 -> 0 | F44: =KA!L44 -> 0 | G44: =KA!M44 -> 0 | H44: =KA!N44 -> 0 | ... L44: =KA!R44 -> 673583 | N44: Honey Poultry Feeds_x000D_ | O44: 877923
A45: =KA!G45 -> Direct - Inactive | B45: =KA!H45 -> Harish Poultry Farm- Mandya | C45: =KA!I45 -> 13280 | D45: =KA!J45 -> 0 | E45: =KA!K45 -> 0 | F45: =KA!L45 -> 0 | G45: =KA!M45 -> 0 | H45: =KA!N45 -> 0 | ... L45: =KA!R45 -> 0 | N45: Hunter Chicken & Eggs India (OPC) Pvt Ltd | O45: 2118932
A46: =KA!G46 -> Direct - Inactive | B46: =KA!H46 -> Hunter Chicken & Eggs India (OPC) Pvt Ltd | C46: =KA!I46 -> 753532 | D46: =KA!J46 -> 0 | E46: =KA!K46 -> 0 | F46: =KA!L46 -> 0 | G46: =KA!M46 -> 0 | H46: =KA!N46 -> 0 | ... L46: =KA!R46 -> 753532 | N46: J K Agencies | O46: 10601021
... A48: =KA!G48 -> Direct - Inactive | B48: =KA!H48 -> Jayanthi Associates, Kannur | C48: =KA!I48 -> 3222982 | D48: =KA!J48 -> 0 | E48: =KA!K48 -> 0 | F48: =KA!L48 -> 0 | G48: =KA!M48 -> 0 | H48: =KA!N48 -> 0 | ... L48: =KA!R48 -> 3222982 | N48: Javare Gowda Dairy Farm | O48: 8815
A49: =KA!G49 -> Direct - Inactive | B49: =KA!H49 -> Jayaraju Poultry Farm_x000D_ | C49: =KA!I49 -> 296940 | D49: =KA!J49 -> 0 | E49: =KA!K49 -> 0 | F49: =KA!L49 -> 0 | G49: =KA!M49 -> 0 | H49: =KA!N49 -> 0 | ... L49: =KA!R49 -> 296940 | N49: Jaya Kumar Poultry Farm | O49: 3824600 | Q49: =VLOOKUP(N49,'SD with Cr bal'!$D$3:$E$99,2,0) -> 45 | R49: =GETPIVOTDATA("Pending Bills",$N$1,"Particulars","Jaya Kumar Poultry Farm")-Q49 -> 3824555
A50: =KA!G50 -> Direct - Inactive | B50: =KA!H50 -> J K Pig Farm, Chllakere | C50: =KA!I50 -> 1639250 | D50: =KA!J50 -> 0 | E50: =KA!K50 -> 0 | F50: =KA!L50 -> 0 | G50: =KA!M50 -> 0 | H50: =KA!N50 -> 0 | ... L50: =KA!R50 -> 1639250 | N50: Jayalinga Poultry Farm | O50: 131750
A51: =KA!G51 -> Direct - Inactive | B51: =KA!H51 -> Jyothi Poultry Farm | C51: =KA!I51 -> 53935 | D51: =KA!J51 -> 0 | E51: =KA!K51 -> 0 | F51: =KA!L51 -> 0 | G51: =KA!M51 -> 0 | H51: =KA!N51 -> 0 | ... L51: =KA!R51 -> 0 | N51: Jayanthi Associates, Kannur | O51: 3222982
A52: =KA!G52 -> Direct - Inactive | B52: =KA!H52 -> Kannadiga Poultry Farm | C52: =KA!I52 -> 950 | D52: =KA!J52 -> 0 | E52: =KA!K52 -> 0 | F52: =KA!L52 -> 0 | G52: =KA!M52 -> 0 | H52: =KA!N52 -> 0 | ... L52: =KA!R52 -> 0 | N52: Jayaraju Poultry Farm_x000D_ | O52: 296940
A53: =KA!G53 -> Direct - Inactive | B53: =KA!H53 -> Kempanna Poultry Farm | C53: =KA!I53 -> 4350 | D53: =KA!J53 -> 0 | E53: =KA!K53 -> 0 | F53: =KA!L53 -> 0 | G53: =KA!M53 -> 0 | H53: =KA!N53 -> 0 | ... L53: =KA!R53 -> 0 | N53: Jeelan Poultry Farm | O53: 173480
A54: =KA!G54 -> Direct - Inactive | B54: =KA!H54 -> Krishna Murthy Labour | C54: =KA!I54 -> 2000 | D54: =KA!J54 -> 0 | E54: =KA!K54 -> 0 | F54: =KA!L54 -> 0 | G54: =KA!M54 -> 0 | H54: =KA!N54 -> 0 | ... L54: =KA!R54 -> 0 | N54: Jogi Gowda Poultry Farm | O54: 86330
A55: =KA!G55 -> Direct - Inactive | B55: =KA!H55 -> Krishnappa | C55: =KA!I55 -> 594147.4 | D55: =KA!J55 -> 0 | E55: =KA!K55 -> 0 | F55: =KA!L55 -> 0 | G55: =KA!M55 -> 0 | H55: =KA!N55 -> 0 | ... L55: =KA!R55 -> 594147.4 | N55: Jyothi Poultry Farm | O55: 53935
A56: =KA!G56 -> Direct - Inactive | B56: =KA!H56 -> Krushie Kushie C/O Rakshitha | C56: =KA!I56 -> 864426 | D56: =KA!J56 -> 0 | E56: =KA!K56 -> 0 | F56: =KA!L56 -> 0 | G56: =KA!M56 -> 0 | H56: =KA!N56 -> 0 | ... L56: =KA!R56 -> 0 | N56: Jyothi Poultry Farms | O56: 81564.16
A57: =KA!G57 -> Direct - Inactive | B57: =KA!H57 -> Lalitha Farm, Kadur | C57: =KA!I57 -> 36700 | D57: =KA!J57 -> 0 | E57: =KA!K57 -> 0 | F57: =KA!L57 -> 0 | G57: =KA!M57 -> 0 | H57: =KA!N57 -> 0 | ... L57: =KA!R57 -> 36700 | N57: K G Satya Poultry Farm | O57: 367278
A58: =KA!G58 -> Direct - Inactive | B58: =KA!H58 -> Madduramma Poultry Farm | C58: =KA!I58 -> 76200 | D58: =KA!J58 -> 0 | E58: =KA!K58 -> 0 | F58: =KA!L58 -> 0 | G58: =KA!M58 -> 0 | H58: =KA!N58 -> 0 | ... L58: =KA!R58 -> 76200 | N58: K P R fresh products | O58: 72657.64
A59: =KA!G59 -> Direct - Inactive | B59: =KA!H59 -> Megha Poultry Farm | C59: =KA!I59 -> 317430 | D59: =KA!J59 -> 0 | E59: =KA!K59 -> 0 | F59: =KA!L59 -> 0 | G59: =KA!M59 -> 0 | H59: =KA!N59 -> 0 | ... L59: =KA!R59 -> 317430 | N59: K Satya Padma Latha | O59: 117261
A60: =KA!G60 -> Direct - Inactive | B60: =KA!H60 -> M.Nataraja S/O M.R.Muniswamy | C60: =KA!I60 -> 101265 | D60: =KA!J60 -> 0 | E60: =KA!K60 -> 0 | F60: =KA!L60 -> 0 | G60: =KA!M60 -> 0 | H60: =KA!N60 -> 0 | ... L60: =KA!R60 -> 101265 | N60: K V R Poultry Farm | O60: 202127
...

Sheet SD with Cr bal
A1: SD Credit Balance as of 31st July 2026
A3: DBS | B3: Credit | D3: Particulars | E3: Credit | J3: Particulars | K3: Credit
A4: A-One Poultry Feed | B4: 2690 | D4: =A4 -> A-One Poultry Feed | E4: =B4 -> 2690 | J4: Aditi Enterprises | K4: 8500
A5: Bharath Malnad Farms_x000D_ | B5: 1250 | D5: =A5 -> Bharath Malnad Farms_x000D_ | E5: =B5 -> 1250 | J5: Akash Poultry Farm | K5: 246514
A6: Komala Poultry | B6: 100 | D6: =A6 -> Komala Poultry | E6: =B6 -> 100 | J6: Ali poultry farms | K6: 1500
A7: Lotus Enterprises | B7: 135000 | D7: =A7 -> Lotus Enterprises | E7: =B7 -> 135000 | J7: A-One Poultry Feed | K7: 2690
A8: M.A. Haji Poultry Farm | B8: 18800 | D8: =A8 -> M.A. Haji Poultry Farm | E8: =B8 -> 18800 | J8: Bharath Malnad Farms_x000D_ | K8: 1250
A9: SR Agro Farms | B9: 14554 | D9: =A9 -> SR Agro Farms | E9: =B9 -> 14554 | J9: Bharat Poultry Farms | K9: 53814
A10: Sri Krishna Sai Farms | B10: 41550 | D10: =A10 -> Sri Krishna Sai Farms | E10: =B10 -> 41550 | J10: Demo | K10: 176390
A11: Sri Puradamma Poultry Feeds & Form | B11: 29375 | D11: =A11 -> Sri Puradamma Poultry Feeds & Form | E11: =B11 -> 29375 | J11: Devi Poultry Farm | K11: 11006.95
A12: Sunbiotic Animal Health Pvt Ltd | B12: 4615.25 | D12: =A12 -> Sunbiotic Animal Health Pvt Ltd | E12: =B12 -> 4615.25 | J12: Gouthami Poultry Farm | K12: 15700
B13: =SUM(B4:B12) -> 247934.25 | D13: =A15 -> Masthan Poultry Farm | E13: =B15 -> 340 | J13: G.V.Soma Raju Poultry Farm | K13: 12214.54
A14: Hosur | D14: =A16 -> M M Traders | E14: =B16 -> 1000 | J14: Ideal Ventures | K14: 1390
A15: Masthan Poultry Farm | B15: 340 | D15: =A17 -> Siva Reddy Poultry Farm | E15: =B17 -> 6961 | J15: Komala Poultry | K15: 100
A16: M M Traders | B16: 1000 | D16: =A18 -> SJ Traders | E16: =B18 -> 400 | J16: Krishna Agri Vet | K16: 7200
A17: Siva Reddy Poultry Farm | B17: 6961 | D17: =A21 -> Krishna Agri Vet | E17: =B21 -> 7200 | J17: Maddur Taluk Koli Sakanike Raitra Sahakara Sangha | K17: 21647
A18: SJ Traders | B18: 400 | D18: =A22 -> Nagendra Nayak | E18: =B22 -> 2000 | J18: M.A. Haji Poultry Farm | K18: 18800
B19: =SUM(B15:B18) -> 8701 | D19: =A23 -> Shakthiman Poultry Farm | E19: =B23 -> 4104 | J19: Masthan Poultry Farm | K19: 340
A20: Hubli | D20: =A26 -> GMI Poultry Foods | E20: =B26 -> 90000 | J20: Nagabhushanarao Poultry Farm | K20: 5605.12
A21: Krishna Agri Vet | B21: 7200 | D21: =A27 -> Gouthami Poultry Farm | E21: =B27 -> 15700 | J21: Nagendra Nayak | K21: 2000
A22: Nagendra Nayak | B22: 2000 | D22: =A28 -> Laxmi Sai Breeding Farms Pvt Ltd | E22: =B28 -> 10399 | J22: Nalluri phanikumar | K22: 1247
A23: Shakthiman Poultry Farm | B23: 4104 | D23: =A29 -> Mahadeva Poultry Farm | E23: =B29 -> 8136 | J23: Nandini Poultry Farm _x000D_ | K23: 77704.07
B24: =SUM(B21:B23) -> 13304 | D24: =A30 -> Nandina Poultry Complex | E24: =B30 -> 3.36 | J24: Natural Remedies Pvt Ltd, TN | K24: 17057.75
A25: Jamuna | D25: =A31 -> N Mallikharjunarao Poultry farm | E25: =B31 -> 31900 | J25: N Subbarao | K25: 9881
A26: GMI Poultry Foods | B26: 90000 | D26: =A32 -> Prabhavathi Sunrice Poultry | E26: =B32 -> 28800 | J26: Prabhavathi Sunrice Poultry | K26: 28800
A27: Gouthami Poultry Farm | B27: 15700 | D27: =A33 -> Samakka Sarakka Poultry farms | E27: =B33 -> 8175 | J27: Ramalinge Gowda Poultry Farm | K27: 2255
A28: Laxmi Sai Breeding Farms Pvt Ltd | B28: 10399 | D28: =A34 -> Shashidhara Poultry Form | E28: =B34 -> 10920 | J28: Satyanarayana Poultries _x000D_ | K28: 10049.54
A29: Mahadeva Poultry Farm | B29: 8136 | D29: =A35 -> Srinivasa Poultry Farm | E29: =B35 -> 9454.94 | J29: Sekhar poultry Farm | K29: 188002
A30: Nandina Poultry Complex | B30: 3.36 | D30: =A36 -> Sri Sai Poultry Farm | E30: =B36 -> 9719.3 | J30: Shivarudra Poultry Farm | K30: 70423
A31: N Mallikharjunarao Poultry farm | B31: 31900 | D31: =A37 -> Sri Siddi Vinayaka Agro Centre | E31: =B37 -> 448000 | J31: Slv Cattle Feeds | K31: 5000
A32: Prabhavathi Sunrice Poultry | B32: 28800 | D32: =A38 -> S S Poultry Farm | E32: =B38 -> 100750 | J32: SR Agro Farms | K32: 14554
A33: Samakka Sarakka Poultry farms | B33: 8175 | D33: =A41 -> Aditi Enterprises | E33: =B41 -> 8500 | J33: Sribala Balaji Srinivasa PF | K33: 46604
A34: Shashidhara Poultry Form | B34: 10920 | D34: =A42 -> CKS Poultry Farm | E34: =B42 -> 3000 | J34: Sri Devi Durga Poultry Farm | K34: 7965
A35: Srinivasa Poultry Farm | B35: 9454.94 | D35: =A43 -> Siva Reddy Poultry Farm | E35: =B43 -> 4000 | J35: Sri Gayathri Poultry Farm | K35: 6613
A36: Sri Sai Poultry Farm | B36: 9719.3 | D36: =A44 -> Slv Cattle Feeds | E36: =B44 -> 5000 | J36: Sri Lakshmi Narasimha Poultry & Goat Farm | K36: 500
A37: Sri Siddi Vinayaka Agro Centre | B37: 448000 | D37: =A45 -> Sri Lakshmi Narasimha Poultry & Goat Farm | E37: =B45 -> 500 | J37: Sri Manjunatha Agencies | K37: 1750
A38: S S Poultry Farm | B38: 100750 | D38: =A48 -> Akash Poultry Farm | E38: =B48 -> 246514 | J38: Sri Puradamma Poultry Feeds & Form | K38: 29375
B39: =SUM(B26:B38) -> 771957.6 | D39: =A49 -> Anilkumar Poultry Farm | E39: =B49 -> 575 | J39: Sri Sai Harsha Poultry Farm | K39: 18876
A40: Komarla | D40: =A50 -> Byraveshwara Poultry & Cattel Feeds _x000D_ | E40: =B50 -> 129963 | J40: Sri Satya Poultries | K40: 1074.52
A41: Aditi Enterprises | B41: 8500 | D41: =A51 -> Demo | E41: =B51 -> 176390 | J41: Sri Venkateshwara Poultry Farm_x000D_ | K41: 11349.5
...

Sheet Dileep & Team
B1: =A3 -> Adarsh | C1: SD Ageing Report as of 31/07/2026
A2: ASM | B2: Particulars | C2: Pending Bills | D2: (< 15 days ) | E2: 15 to 30 days | F2: 30 to 45 days | G2: 45 to 60 days | H2: 60 to 90 days | I2: 90 to 180 days | J2: 180 to 365 days | K2: 365 to 730 days | L2: (> 730 days ) | N2: Bal as on 30.06.2026 | O2: Remarks on 07/07/2026
A3: Adarsh | B3: Haritha Agencies | C3: 430700 | D3: 430700 | E3: 0 | F3: 0 | G3: 0 | H3: 0 | I3: 0 | J3: 0 | K3: 0 | L3: 0
A4: Adarsh | B4: Ras Traders | C4: 190900 | D4: 0 | E4: 0 | F4: 0 | G4: 190900 | H4: 0 | I4: 0 | J4: 0 | K4: 0 | L4: 0 | N4: 340900
A5: Adarsh | B5: Royal Traders | C5: 475 | D5: 0 | E5: 0 | F5: 0 | G5: 475 | H5: 0 | I5: 0 | J5: 0 | K5: 0 | L5: 0
B6: Total | C6: =SUBTOTAL(109,Table2[Pending Bills]) -> 622075 | D6: =SUBTOTAL(109,Table2[(< 15 days )]) -> 430700 | E6: =SUBTOTAL(109,Table2[15 to 30 days]) -> 0 | F6: =SUBTOTAL(109,Table2[30 to 45 days]) -> 0 | G6: =SUBTOTAL(109,Table2[45 to 60 days]) -> 191375 | H6: =SUBTOTAL(109,Table2[60 to 90 days]) -> 0 | I6: =SUBTOTAL(109,Table2[90 to 180 days]) -> 0 | J6: =SUBTOTAL(109,Table2[180 to 365 days]) -> 0 | K6: =SUBTOTAL(109,Table2[365 to 730 days]) -> 0 | L6: =SUBTOTAL(109,Table2[(> 730 days )]) -> 0
B8: =A10 -> Nebu John | C8: SD Ageing Report as of 31/07/2026
A9: ASM | B9: Particulars | C9: Pending Bills | D9: (< 15 days ) | E9: 15 to 30 days | F9: 30 to 45 days | G9: 45 to 60 days | H9: 60 to 90 days | I9: 90 to 180 days | J9: 180 to 365 days | K9: 365 to 730 days | L9: (> 730 days ) | N9: Bal as on 30.06.2026 | O9: Remarks on 07/07/2026
A10: Nebu John | B10: Bismillah Feeds | C10: 3013130 | D10: 572360 | E10: 2440770 | F10: 0 | G10: 0 | H10: 0 | I10: 0 | J10: 0 | K10: 0 | L10: 0 | N10: 4203202.4 | O10: Below 30 days by 31/07
A11: Nebu John | B11: Bismillah Feeds | C11: 2893087.4 | D11: 0 | E11: 2893087.4 | F11: 0 | G11: 0 | H11: 0 | I11: 0 | J11: 0 | K11: 0 | L11: 0 | N11: 1585361 | O11: Below 30 days by 31/07
A12: Nebu John | B12: J K Agencies | C12: 1311295 | D12: 0 | E12: 1311295 | F12: 0 | G12: 0 | H12: 0 | I12: 0 | J12: 0 | K12: 0 | L12: 0 | O12: Bring below 150 and below 30 days
A13: Nebu John | B13: J K Agencies | C13: 9289726 | D13: 9289726 | E13: 0 | F13: 0 | G13: 0 | H13: 0 | I13: 0 | J13: 0 | K13: 0 | L13: 0 | N13: 11675425 | O13: Bring below 150 and below 30 days
A14: Nebu John | B14: M S Feeds | C14: 3252785 | D14: 3252785 | E14: 0 | F14: 0 | G14: 0 | H14: 0 | I14: 0 | J14: 0 | K14: 0 | L14: 0 | N14: 2270250
A15: Nebu John | B15: Matha Agencies | C15: 5070634 | D15: 1514350 | E15: 3556284 | F15: 0 | G15: 0 | H15: 0 | I15: 0 | J15: 0 | K15: 0 | L15: 0 | N15: 5811240 | O15: Bring below 150 and below 30 days
A16: Nebu John | B16: MPM Agencies | C16: 96900 | D16: 96900 | E16: 0 | F16: 0 | G16: 0 | H16: 0 | I16: 0 | J16: 0 | K16: 0 | L16: 0
A17: Nebu John | B17: Quality Feeds | C17: 234300 | D17: 234300 | E17: 0 | F17: 0 | G17: 0 | H17: 0 | I17: 0 | J17: 0 | K17: 0 | L17: 0
A18: Nebu John | B18: Quality Feeds | C18: 2430726 | D18: 2430726 | E18: 0 | F18: 0 | G18: 0 | H18: 0 | I18: 0 | J18: 0 | K18: 0 | L18: 0 | N18: 2527976
B19: Total | C19: =SUBTOTAL(109,C10:C18) -> 27592583 | D19: =SUBTOTAL(109,D10:D18) -> 17391147 | E19: =SUBTOTAL(109,E10:E18) -> 10201436 | F19: =SUBTOTAL(109,F10:F18) -> 0 | G19: =SUBTOTAL(109,G10:G18) -> 0 | H19: =SUBTOTAL(109,H10:H18) -> 0 | I19: =SUBTOTAL(109,I10:I18) -> 0 | J19: =SUBTOTAL(109,J10:J18) -> 0 | ... L19: =SUBTOTAL(109,L10:L18) -> 0
B21: =A23 -> Raja Kumar | C21: SD Ageing Report as of 31/07/2026
A22: ASM | B22: Particulars | C22: Pending Bills | D22: (< 15 days ) | E22: 15 to 30 days | F22: 30 to 45 days | G22: 45 to 60 days | H22: 60 to 90 days | I22: 90 to 180 days | J22: 180 to 365 days | K22: 365 to 730 days | L22: (> 730 days ) | N22: Bal as on 30.06.2026 | O22: Remarks on 07/07/2026
A23: Raja Kumar | B23: Rishan Exporters | C23: 3484675 | D23: 3484675 | E23: 0 | F23: 0 | G23: 0 | H23: 0 | I23: 0 | J23: 0 | K23: 0 | L23: 0 | N23: 5105419
A24: Raja Kumar | B24: Rishan Exporters | C24: 3159329 | D24: 3159329 | E24: 0 | F24: 0 | G24: 0 | H24: 0 | I24: 0 | J24: 0 | K24: 0 | L24: 0 | N24: 2055335
A25: Raja Kumar | B25: S I T Agencies | C25: 832050 | D25: 0 | E25: 0 | F25: 0 | G25: 668100 | H25: 0 | I25: 163950 | J25: 0 | K25: 0 | L25: 0 | N25: 2820811
A26: Raja Kumar | B26: S I T Agencies | C26: 2685011 | D26: 0 | E26: 683100 | F26: 0 | G26: 892375 | H26: 1109536 | I26: 0 | J26: 0 | K26: 0 | L26: 0 | N26: 1032050 | O26: 12.5 L before Jul end.
B27: Total | C27: =SUBTOTAL(109,C23:C26) -> 10161065 | D27: =SUBTOTAL(109,D23:D26) -> 6644004 | E27: =SUBTOTAL(109,E23:E26) -> 683100 | F27: =SUBTOTAL(109,F23:F26) -> 0 | G27: =SUBTOTAL(109,G23:G26) -> 1560475 | H27: =SUBTOTAL(109,H23:H26) -> 1109536 | I27: =SUBTOTAL(109,I23:I26) -> 163950 | J27: =SUBTOTAL(109,J23:J26) -> 0 | ... L27: =SUBTOTAL(109,L23:L26) -> 0
B29: Grand Total | C29: =+C27+C19+Table2[[#Totals],[Pending Bills]] -> 38375723 | D29: =+D27+D19+Table2[[#Totals],[(< 15 days )]] -> 24465851 | E29: =+E27+E19+Table2[[#Totals],[15 to 30 days]] -> 10884536 | F29: =+F27+F19+Table2[[#Totals],[30 to 45 days]] -> 0 | G29: =+G27+G19+Table2[[#Totals],[45 to 60 days]] -> 1751850 | H29: =+H27+H19+Table2[[#Totals],[60 to 90 days]] -> 1109536 | I29: =+I27+I19+Table2[[#Totals],[90 to 180 days]] -> 163950 | J29: =+J27+J19+Table2[[#Totals],[180 to 365 days]] -> 0 | K29: =+K27+K19+Table2[[#Totals],[365 to 730 days]] -> 0 | L29: =+L27+L19+Table2[[#Totals],[(> 730 days )]] -> 0 | N29: =SUM(N4:N27) -> 39427969

Sheet Ashok & Team
B1: =+A3 -> Ashok | C1: SD Ageing Report as of 31/07/2026
A2: ASM | B2: Particulars | C2: Pending Bills | D2: (< 15 days ) | E2: 15 to 30 days | F2: 30 to 45 days | G2: 45 to 60 days | H2: 60 to 90 days | I2: 90 to 180 days | J2: 180 to 365 days | K2: 365 to 730 days | L2: (> 730 days ) | N2: Bal as on 30.06.2026 | O2: Remarks on 06/07/2026
A3: Ashok | B3: Lotus Enterprises | C3: =5607262.15-135000 -> 5472262.2 | D3: 4005000 | E3: 1235900 | F3: =366362.15-135000 -> 231362.15 | G3: 0 | H3: 0 | I3: 0 | J3: 0 | K3: 0 | L3: 0 | N3: 4966362.2
A4: Ashok | B4: Shree Agencies | C4: 5742269.8 | D4: 5742269.8 | E4: 0 | F4: 0 | G4: 0 | H4: 0 | I4: 0 | J4: 0 | K4: 0 | L4: 0 | N4: 5490716.6
A5: Ashok | B5: Snehith Reddy Poultry And Feeds | C5: 812230.48 | D5: 812230.48 | E5: 0 | F5: 0 | G5: 0 | H5: 0 | I5: 0 | J5: 0 | K5: 0 | L5: 0 | N5: 1621083.3
B6: Total | C6: =SUBTOTAL(109,Table5[Pending Bills]) -> 12026762 | D6: =SUBTOTAL(109,Table5[(< 15 days )]) -> 10559500 | E6: =SUBTOTAL(109,Table5[15 to 30 days]) -> 1235900 | F6: =SUBTOTAL(109,Table5[30 to 45 days]) -> 231362.15 | G6: =SUBTOTAL(109,Table5[45 to 60 days]) -> 0 | H6: =SUBTOTAL(109,Table5[60 to 90 days]) -> 0 | I6: =SUBTOTAL(109,Table5[90 to 180 days]) -> 0 | J6: =SUBTOTAL(109,Table5[180 to 365 days]) -> 0 | K6: =SUBTOTAL(109,Table5[365 to 730 days]) -> 0 | L6: =SUBTOTAL(109,Table5[(> 730 days )]) -> 0
B8: =+A10 -> Bandaru Balaji | C8: SD Ageing Report as of 31/07/2026
A9: ASM | B9: Particulars | C9: Pending Bills | D9: (< 15 days ) | E9: 15 to 30 days | F9: 30 to 45 days | G9: 45 to 60 days | H9: 60 to 90 days | I9: 90 to 180 days | J9: 180 to 365 days | K9: 365 to 730 days | L9: (> 730 days ) | N9: Bal as on 30.06.2026 | O9: Remarks on 06/07/2026
A10: Bandaru Balaji | B10: Dhanalakshmi poultry farm | C10: 319.65 | D10: 319.65 | E10: 0 | F10: 0 | G10: 0 | H10: 0 | I10: 0 | J10: 0 | K10: 0 | L10: 0
A11: Bandaru Balaji | B11: Sri Parameshwari Broiler Poultry Farm & Feeds | C11: 496246.81 | D11: 496246.81 | E11: 0 | F11: 0 | G11: 0 | H11: 0 | I11: 0 | J11: 0 | K11: 0 | L11: 0
A12: Bandaru Balaji | B12: Sri Parameshwari Broiler Poultry Farm & Feeds | C12: 417103 | D12: 417103 | E12: 0 | F12: 0 | G12: 0 | H12: 0 | I12: 0 | J12: 0 | K12: 0 | L12: 0 | N12: 52787.16
B13: Total | C13: =SUBTOTAL(109,Table6[Pending Bills]) -> 913669.46 | D13: =SUBTOTAL(109,Table6[(< 15 days )]) -> 913669.46 | E13: =SUBTOTAL(109,Table6[15 to 30 days]) -> 0 | F13: =SUBTOTAL(109,Table6[30 to 45 days]) -> 0 | G13: =SUBTOTAL(109,Table6[45 to 60 days]) -> 0 | H13: =SUBTOTAL(109,Table6[60 to 90 days]) -> 0 | I13: =SUBTOTAL(109,Table6[90 to 180 days]) -> 0 | J13: =SUBTOTAL(109,Table6[180 to 365 days]) -> 0 | K13: =SUBTOTAL(109,Table6[365 to 730 days]) -> 0 | L13: =SUBTOTAL(109,Table6[(> 730 days )]) -> 0
B15: =+A17 -> Karre Narasimha | C15: SD Ageing Report as of 31/07/2026
A16: ASM | B16: Particulars | C16: Pending Bills | D16: (< 15 days ) | E16: 15 to 30 days | F16: 30 to 45 days | G16: 45 to 60 days | H16: 60 to 90 days | I16: 90 to 180 days | J16: 180 to 365 days | K16: 365 to 730 days | L16: (> 730 days ) | N16: Bal as on 30.06.2026 | O16: Remarks on 06/07/2026
A17: Karre Narasimha | B17: K P R fresh products | C17: 72657.64 | D17: 0 | E17: 0 | F17: 0 | G17: 0 | H17: 0 | I17: 0 | J17: 0 | K17: 72657.64 | L17: 0 | N17: 72657.64 | O17: Wl collect before 10th Jul
A18: Karre Narasimha | B18: Kishan poultry society | C18: 340 | D18: 340 | E18: 0 | F18: 0 | G18: 0 | H18: 0 | I18: 0 | J18: 0 | K18: 0 | L18: 0
A19: Karre Narasimha | B19: Mallikharjuna Rao Poultry Farm | C19: 700 | D19: 0 | E19: 0 | F19: 0 | G19: 0 | H19: 0 | I19: 700 | J19: 0 | K19: 0 | L19: 0 | N19: 13000
A20: Karre Narasimha | B20: Narender Reddy poultry farms | C20: 5200 | D20: 0 | E20: 5200 | F20: 0 | G20: 0 | H20: 0 | I20: 0 | J20: 0 | K20: 0 | L20: 0
B21: Total | C21: =SUBTOTAL(109,Table7[Pending Bills]) -> 78897.64 | D21: =SUBTOTAL(109,Table7[(< 15 days )]) -> 340 | E21: =SUBTOTAL(109,Table7[15 to 30 days]) -> 5200 | F21: =SUBTOTAL(109,Table7[30 to 45 days]) -> 0 | G21: =SUBTOTAL(109,Table7[45 to 60 days]) -> 0 | H21: =SUBTOTAL(109,Table7[60 to 90 days]) -> 0 | I21: =SUBTOTAL(109,Table7[90 to 180 days]) -> 700 | J21: =SUBTOTAL(109,Table7[180 to 365 days]) -> 0 | K21: =SUBTOTAL(109,Table7[365 to 730 days]) -> 72657.64 | L21: =SUBTOTAL(109,Table7[(> 730 days )]) -> 0
B23: =A25 -> N. Srinivas | C23: SD Ageing Report as of 31/07/2026
A24: ASM | B24: Particulars | C24: Pending Bills | D24: (< 15 days ) | E24: 15 to 30 days | F24: 30 to 45 days | G24: 45 to 60 days | H24: 60 to 90 days | I24: 90 to 180 days | J24: 180 to 365 days | K24: 365 to 730 days | L24: (> 730 days ) | N24: Bal as on 30.06.2026 | O24: Remarks on 06/07/2026
A25: N. Srinivas | B25: M/s Excel Poultry | C25: 60000 | D25: 0 | E25: 60000 | F25: 0 | G25: 0 | H25: 0 | I25: 0 | J25: 0 | K25: 0 | L25: 0
A26: N. Srinivas | B26: Masthan Poultry Farms | C26: 198547.2 | D26: 0 | E26: 0 | F26: 0 | G26: 0 | H26: 0 | I26: 0 | J26: 198547.2 | K26: 0 | L26: 0 | N26: 198547.2
A27: N. Srinivas | B27: Sri sreshta Poultries and feed | C27: 709.98 | D27: 0 | E27: 0 | F27: 0 | G27: 0 | H27: 0 | I27: 709.98 | J27: 0 | K27: 0 | L27: 0 | N27: 709.98
